Workbook

Sheet 最新追加任务情况
F1: 是否包含核心重点 | G1: 是否之前已登记 | L1: NEW-M1-农林牧渔-生猪价格
A2: 1-行业经济 | B2: 行业经济\交运\日 | C2: NEW-DWMY-交运-中航信-当日预定指数-日-人工 | D2: 日 | E2: =VLOOKUP(C2,任务详情!B:E,4,0) -> 1 | F2: 否 | G2: 是 | H2: 模版频率 | I2: 点击不处理后追加 | L2: NEW-M7-化工-隆众进出口-原盐就出口(月)
A3: 1-行业经济 | B3: 行业经济\交运\日 | C3: NEW-DWMY-交运-中航信-需求指数-人工 | D3: 日 | E3: =VLOOKUP(C3,任务详情!B:E,4,0) -> 1 | F3: 是 | G3: 是 | H3: 日 | I3: 1 | L3: NEW-Q3-金融-行业协会-基金业:资产管理行业数据
A4: 1-行业经济 | B4: 行业经济\化工\半周 | C4: NEW-HW1-化工-库存模板-丙酮江阴库存-人工 | D4: 日 | E4: =VLOOKUP(C4,任务详情!B:E,4,0) -> 1 | F4: 是 | G4: 是 | H4: 不定期 | I4: 1 | L4: 新宏观-Y10-国统局资源和环境-分省-水资源
A5: 1-行业经济 | B5: 行业经济\化工\半周 | C5: NEW-HW1-化工-库存模板-华东主港乙二醇库存及主流库区统计分析-人工 | D5: 日 | E5: =VLOOKUP(C5,任务详情!B:E,4,0) -> 1 | F5: 是 | G5: 是 | H5: 周 | I5: 1 | L5: NEW-W1-煤炭-CCTD秦皇岛动力煤价格
A6: 1-行业经济 | B6: 行业经济\化工\半周 | C6: NEW-HW1-化工-库存模板-华东乙二醇码头库存-人工 | D6: 日 | E6: =VLOOKUP(C6,任务详情!B:E,4,0) -> 1 | F6: 是 | G6: 是 | H6: 旬 | I6: 1 | L6: NEW-D8-化工-化纤
A7: 1-行业经济 | B7: 行业经济\化工\半周 | C7: NEW-HW1-化工-库存模板-苯酚江阴港口库存-人工 | D7: 日 | E7: =VLOOKUP(C7,任务详情!B:E,4,0) -> 1 | F7: 否 | G7: 是 | H7: 月 | I7: 3 | L7: 新宏观-Y1-国统局-最新发布-国民经济
A8: 1-行业经济 | B8: 行业经济\TMT\日 | C8: NEW-D1-TMT-每日票房-人工 | D8: 日 | E8: =VLOOKUP(C8,任务详情!B:E,4,0) -> 1 | F8: 否 | G8: 是 | H8: 季 | I8: 3 | L8: 新宏观-M1-wind-中国一致性预期-贸易顺差-1
A9: 1-行业经济 | B9: 行业经济\TMT\日 | C9: NEW-D1-TMT-每日票房-自动化 | D9: 日 | E9: =VLOOKUP(C9,任务详情!B:E,4,0) -> 1 | F9: 否 | G9: 是 | H9: 半年 | I9: 3 | L9: NEW-Y1-金融-证券基金业-私募基金行业
A10: 1-行业经济 | B10: 行业经济\交运\日 | C10: NEW-D1-交运-BDI-人工 | D10: 日 | E10: =VLOOKUP(C10,任务详情!B:E,4,0) -> 1 | F10: 是 | G10: 是 | H10: 年 | I10: 10 | L10: 新宏观-M1-证监会-2
A11: 1-行业经济 | B11: 行业经济\交运\日 | C11: NEW-D1-交运-FDI-人工 | D11: 日 | E11: =VLOOKUP(C11,任务详情!B:E,4,0) -> 1 | F11: 是 | G11: 是 | L11: NEW-M2-医药-中药材指数
A12: 1-行业经济 | B12: 行业经济\交运\日 | C12: NEW-D1-交运-中国水运网运价-人工 | D12: 日 | E12: =VLOOKUP(C12,任务详情!B:E,4,0) -> 1 | F12: 否 | G12: 是 | L12: 新宏观-M1-山东省统计局-公共数据
A13: 1-行业经济 | B13: 行业经济\交运\日 | C13: NEW-D1-交运-中国进口原油运价-人工 | D13: 日 | E13: =VLOOKUP(C13,任务详情!B:E,4,0) -> 1 | F13: 是 | G13: 是 | L13: 【经营数据】-食品饮料-HY1-颐海国际
A14: 1-行业经济 | B14: 行业经济\交运\日 | C14: NEW-D1-交运-全球集装箱-自动化 | D14: 日 | E14: =VLOOKUP(C14,任务详情!B:E,4,0) -> 1 | F14: 否 | G14: 是 | L14: 地方经济运行-M1-云南(非重点)-丽江市-宁蒗彝族自治县
A15: 1-行业经济 | B15: 行业经济\交运\日 | C15: NEW-D1-交运-周涨跌幅衍生计算-人工 | D15: 日 | E15: =VLOOKUP(C15,任务详情!B:E,4,0) -> 1 | F15: 是 | G15: 是 | L15: 地方经济四期-Y1-浙江省统计年鉴-绍兴市统计局
A16: 1-行业经济 | B16: 行业经济\交运\日 | C16: NEW-D1-交运-股指-人工 | D16: 日 | E16: =VLOOKUP(C16,任务详情!B:E,4,0) -> 1 | F16: 是 | G16: 是 | L16: 国际宏观-Y1-欧洲-央行-债务
A17: 1-行业经济 | B17: 行业经济\交运\日 | C17: NEW-D1-交运-股指-自动化 | D17: 日 | E17: =VLOOKUP(C17,任务详情!B:E,4,0) -> 1 | F17: 否 | G17: 是 | L17: 地方经济运行-M1-云南(非重点)-楚雄州-南华县
A18: 1-行业经济 | B18: 行业经济\交运\日 | C18: NEW-D1-交运-运力-CDI-人工 | D18: 日 | E18: =VLOOKUP(C18,任务详情!B:E,4,0) -> 1 | F18: 否 | G18: 是 | L18: NEW-M2-房地产-70大城市房价指数-房价租金比
A19: 1-行业经济 | B19: 行业经济\交运\日 | C19: NEW-D1-交运-运力-分公司-人工 | D19: 日 | E19: =VLOOKUP(C19,任务详情!B:E,4,0) -> 1 | F19: 是 | G19: 是 | L19: NEW-W1-机械设备-庞源指数
A20: 1-行业经济 | B20: 行业经济\交运\日 | C20: NEW-D1-交运-进口干散货运价-人工 | D20: 日 | E20: =VLOOKUP(C20,任务详情!B:E,4,0) -> 1 | F20: 是 | G20: 是 | L20: 地方经济三期-Y35-云南省统计公报-文山州
A21: 1-行业经济 | B21: 行业经济\交运\日 | C21: NEW-D1-交运-远东干散货-自动化 | D21: 日 | E21: =VLOOKUP(C21,任务详情!B:E,4,0) -> 1 | F21: 否 | G21: 是 | L21: 新宏观-Y1-央行-中国区域金融运行报告
A22: 1-行业经济 | B22: 行业经济\交运\日 | C22: NEW-D1-交运-集装箱期租-自动化 | D22: 日 | E22: =VLOOKUP(C22,任务详情!B:E,4,0) -> 1 | F22: 否 | G22: 是 | L22: NEW-D6-钢铁-冶金焦价格
... A1691: 1-行业经济 | B1691: 行业经济\食品饮料\日 | C1691: NEW-D1-食品饮料-鹌鹑蛋-人工 | D1691: 日 | E1691: =VLOOKUP(C1691,任务详情!B:E,4,0) -> 1 | F1691: 否 | G1691: 是 | L1691: 【经营数据】-休闲服务-首旅酒店QHY-首旅酒店-年
A1692: 2-中国宏观 | B1692: #VALUE! | C1692: 新宏观-D1-上海证券交易所-债券成交概况-人工 | D1692: 日 | E1692: =VLOOKUP(C1692,任务详情!B:E,4,0) -> 1 | F1692: 否 | G1692: 是 | L1692: 国际宏观-M1-美国-商务部-制造商的商品
A1693: 2-中国宏观 | B1693: 中国宏观\中国人民银行\日 | C1693: 新宏观-D1-央行货币政策-CBS-自动化 | D1693: 日 | E1693: =VLOOKUP(C1693,任务详情!B:E,4,0) -> 1 | F1693: 否 | G1693: 是 | L1693: NEW-D2-房地产(T)-连云港商品房
A1694: 2-中国宏观 | B1694: 中国宏观\中国人民银行\日 | C1694: 新宏观-D1-央行货币政策-SLO-人工 | D1694: 日 | E1694: =VLOOKUP(C1694,任务详情!B:E,4,0) -> 1 | F1694: 否 | G1694: 是 | L1694: NEW-Y1-钢铁-(人均)表观消费量-W
A1695: 2-中国宏观 | B1695: 中国宏观\中国人民银行\日 | C1695: 新宏观-D1-央行货币政策-再贷款、再贴现利率表-人工 | D1695: 日 | E1695: =VLOOKUP(C1695,任务详情!B:E,4,0) -> 1 | F1695: 否 | G1695: 是 | L1695: NEW-D2-化工-隆众化工-C5C9共聚石油树脂国内市场价
A1696: 2-中国宏观 | B1696: 中国宏观\中国人民银行\日 | C1696: 新宏观-D1-央行货币政策-回购-人工 | D1696: 日 | E1696: =VLOOKUP(C1696,任务详情!B:E,4,0) -> 1 | F1696: 否 | G1696: 是 | L1696: NEW-M1-化工-OPEC-液化气产量
A1697: 2-中国宏观 | B1697: 中国宏观\中国人民银行\日 | C1697: 新宏观-D1-央行货币政策-国库现金管理-人工 | D1697: 日 | E1697: =VLOOKUP(C1697,任务详情!B:E,4,0) -> 1 | F1697: 否 | G1697: 是 | L1697: NEW-M8-房地产-资阳市商品房交易走势
A1698: 2-中国宏观 | B1698: 中国宏观\中国人民银行\日 | C1698: 新宏观-D1-央行货币政策-特别国债-人工 | D1698: 日 | E1698: =VLOOKUP(C1698,任务详情!B:E,4,0) -> 1 | F1698: 否 | G1698: 是 | L1698: NEW-W1-化工-隆众网页-周四-18
A1699: 2-中国宏观 | B1699: 中国宏观\中国外汇交易中心\日 | C1699: 【核心&重点指标】-新宏观-Wind替代数据源-中国外汇交易中心-利率日-自动化 | D1699: 日 | E1699: =VLOOKUP(C1699,任务详情!B:E,4,0) -> 1 | F1699: 否 | G1699: 是 | L1699: NEW-M14-交运-港口数据-新加坡港
A1700: 2-中国宏观 | B1700: 中国宏观\中国外汇交易中心\日 | C1700: 新宏观-D1-中国外汇交易中心-RMBS条件早偿率指数-人工 | D1700: 日 | E1700: =VLOOKUP(C1700,任务详情!B:E,4,0) -> 1 | F1700: 否 | G1700: 是 | L1700: NEW-D2-化工-隆众化工-丙烯酸乙酯国内市场价
A1701: 2-中国宏观 | B1701: 中国宏观\中国外汇交易中心\日 | C1701: 新宏观-D1-中国外汇交易中心-买断式回购日报-自动化 | D1701: 日 | E1701: =VLOOKUP(C1701,任务详情!B:E,4,0) -> 1 | F1701: 否 | G1701: 是 | L1701: NEW-Q1-计算机(需百度)-服务器数据
A1702: 2-中国宏观 | B1702: 中国宏观\中国外汇交易中心\日 | C1702: 新宏观-D1-中国外汇交易中心-利率-自动化 | D1702: 日 | E1702: =VLOOKUP(C1702,任务详情!B:E,4,0) -> 1 | F1702: 否 | G1702: 是 | L1702: NEW-D2-房地产(T)-嘉兴商品房
A1703: 2-中国宏观 | B1703: 中国宏观\中国外汇交易中心\日 | C1703: 新宏观-D1-中国外汇交易中心-利率互换日报-自动化 | D1703: 日 | E1703: =VLOOKUP(C1703,任务详情!B:E,4,0) -> 1 | F1703: 否 | G1703: 是 | L1703: 地方经济运行-M1-云南(非重点)-文山州
A1704: 2-中国宏观 | B1704: 中国宏观\中国外汇交易中心\日 | C1704: 新宏观-D1-中国外汇交易中心-利率互换曲线-自动化 | D1704: 日 | E1704: =VLOOKUP(C1704,任务详情!B:E,4,0) -> 1 | F1704: 否 | G1704: 是 | L1704: NEW-M10-金融市场-期货市场交易情况
... A5497: 4-地方经济 | B5497: 地方经济\月、季频模板\各省、市、区县模板\新疆维吾尔自治区 | C5497: 地方经济运行-M1-新疆(非重点)-巴音郭楞州区县-人工 | D5497: 月 | E5497: =VLOOKUP(C5497,任务详情!B:E,4,0) -> 3 | F5497: 否 | G5497: 是 | L5497: 地方经济运行-M1-云南(非重点)-德宏州-芒市
A5498: 4-地方经济 | B5498: 地方经济\月、季频模板\各省、市、区县模板\新疆维吾尔自治区 | C5498: 地方经济运行-M1-新疆(非重点)-新疆-人工 | D5498: 月 | E5498: =VLOOKUP(C5498,任务详情!B:E,4,0) -> 1 | F5498: 是 | G5498: 是
A5499: 4-地方经济 | B5499: 地方经济\月、季频模板\各省、市、区县模板\新疆维吾尔自治区 | C5499: 地方经济运行-M1-新疆(非重点)-昌吉回族-人工 | D5499: 月 | E5499: =VLOOKUP(C5499,任务详情!B:E,4,0) -> 3 | F5499: 否 | G5499: 是
A5500: 4-地方经济 | B5500: 地方经济\月、季频模板\各省、市、区县模板\新疆维吾尔自治区 | C5500: 地方经济运行-M1-新疆(非重点)-昌吉回族区县-人工 | D5500: 月 | E5500: =VLOOKUP(C5500,任务详情!B:E,4,0) -> 3 | F5500: 否 | G5500: 是
...

Sheet 任务详情
A1: 判断逻辑： | B1: 如果有核心重点指标，默认一天后会再次生成任务。其余按照H:I列时效性追加
A2: 所属模块 | B2: 模版名称 | C2: 模版频率 | D2: 是否核心重点 | E2: 点击不处理后追加调度 | F2: NEW-DWMY-交运-中航信-当日预定指数-日-人工 | G2: =VLOOKUP(F2,B:E,4,0) -> 1 | H2: 模版频率 | I2: 点击不处理后追加
A3: 1-行业经济 | B3: NEW-DWMY-交运-中航信-当日预定指数-日-人工 | C3: 日 | D3: 否 | E3: =VLOOKUP(C3,H:I,2,0) -> 1 | F3: NEW-DWMY-交运-中航信-需求指数-人工 | G3: =VLOOKUP(F3,B:E,4,0) -> 1 | H3: 日 | I3: 1
A4: 1-行业经济 | B4: NEW-DWMY-交运-中航信-需求指数-人工 | C4: 日 | D4: 是 | E4: 1 | F4: NEW-HW1-化工-库存模板-丙酮江阴库存-人工 | G4: =VLOOKUP(F4,B:E,4,0) -> 1 | H4: 不定期 | I4: 1
A5: 1-行业经济 | B5: NEW-HW1-化工-库存模板-丙酮江阴库存-人工 | C5: 日 | D5: 是 | E5: 1 | F5: NEW-HW1-化工-库存模板-华东主港乙二醇库存及主流库区统计分析-人工 | G5: =VLOOKUP(F5,B:E,4,0) -> 1 | H5: 周 | I5: 1
A6: 1-行业经济 | B6: NEW-HW1-化工-库存模板-华东主港乙二醇库存及主流库区统计分析-人工 | C6: 日 | D6: 是 | E6: 1 | F6: NEW-HW1-化工-库存模板-华东乙二醇码头库存-人工 | G6: =VLOOKUP(F6,B:E,4,0) -> 1 | H6: 旬 | I6: 1
A7: 1-行业经济 | B7: NEW-HW1-化工-库存模板-华东乙二醇码头库存-人工 | C7: 日 | D7: 是 | E7: 1 | F7: NEW-HW1-化工-库存模板-苯酚江阴港口库存-人工 | G7: =VLOOKUP(F7,B:E,4,0) -> 1 | H7: 月 | I7: 3
A8: 1-行业经济 | B8: NEW-HW1-化工-库存模板-苯酚江阴港口库存-人工 | C8: 日 | D8: 否 | E8: =VLOOKUP(C8,H:I,2,0) -> 1 | F8: NEW-D1-TMT-每日票房-人工 | G8: =VLOOKUP(F8,B:E,4,0) -> 1 | H8: 季 | I8: 3
A9: 1-行业经济 | B9: NEW-D1-TMT-每日票房-人工 | C9: 日 | D9: 否 | E9: =VLOOKUP(C9,H:I,2,0) -> 1 | F9: NEW-D1-TMT-每日票房-自动化 | G9: =VLOOKUP(F9,B:E,4,0) -> 1 | H9: 半年 | I9: 3
A10: 1-行业经济 | B10: NEW-D1-TMT-每日票房-自动化 | C10: 日 | D10: 否 | E10: =VLOOKUP(C10,H:I,2,0) -> 1 | F10: NEW-D1-交运-BDI-人工 | G10: =VLOOKUP(F10,B:E,4,0) -> 1 | H10: 年 | I10: 10
A11: 1-行业经济 | B11: NEW-D1-交运-BDI-人工 | C11: 日 | D11: 是 | E11: 1 | F11: NEW-D1-交运-FDI-人工 | G11: =VLOOKUP(F11,B:E,4,0) -> 1
A12: 1-行业经济 | B12: NEW-D1-交运-FDI-人工 | C12: 日 | D12: 是 | E12: 1 | F12: NEW-D1-交运-中国水运网运价-人工 | G12: =VLOOKUP(F12,B:E,4,0) -> 1
A13: 1-行业经济 | B13: NEW-D1-交运-中国水运网运价-人工 | C13: 日 | D13: 否 | E13: =VLOOKUP(C13,H:I,2,0) -> 1 | F13: NEW-D1-交运-中国进口原油运价-人工 | G13: =VLOOKUP(F13,B:E,4,0) -> 1
A14: 1-行业经济 | B14: NEW-D1-交运-中国进口原油运价-人工 | C14: 日 | D14: 是 | E14: 1 | F14: NEW-D1-交运-全球集装箱-自动化 | G14: =VLOOKUP(F14,B:E,4,0) -> 1
A15: 1-行业经济 | B15: NEW-D1-交运-全球集装箱-自动化 | C15: 日 | D15: 是 | E15: 1 | F15: NEW-D1-交运-周涨跌幅衍生计算-人工 | G15: =VLOOKUP(F15,B:E,4,0) -> 1
A16: 1-行业经济 | B16: NEW-D1-交运-周涨跌幅衍生计算-人工 | C16: 日 | D16: 是 | E16: 1 | F16: NEW-D1-交运-股指-人工 | G16: =VLOOKUP(F16,B:E,4,0) -> 1
A17: 1-行业经济 | B17: NEW-D1-交运-股指-人工 | C17: 日 | D17: 是 | E17: 1 | F17: NEW-D1-交运-股指-自动化 | G17: =VLOOKUP(F17,B:E,4,0) -> 1
A18: 1-行业经济 | B18: NEW-D1-交运-股指-自动化 | C18: 日 | D18: 是 | E18: 1 | F18: NEW-D1-交运-运力-CDI-人工 | G18: =VLOOKUP(F18,B:E,4,0) -> 1
A19: 1-行业经济 | B19: NEW-D1-交运-运力-CDI-人工 | C19: 日 | D19: 否 | E19: =VLOOKUP(C19,H:I,2,0) -> 1 | F19: NEW-D1-交运-运力-分公司-人工 | G19: =VLOOKUP(F19,B:E,4,0) -> 1
A20: 1-行业经济 | B20: NEW-D1-交运-运力-分公司-人工 | C20: 日 | D20: 是 | E20: 1 | F20: NEW-D1-交运-进口干散货运价-人工 | G20: =VLOOKUP(F20,B:E,4,0) -> 1
A21: 1-行业经济 | B21: NEW-D1-交运-进口干散货运价-人工 | C21: 日 | D21: 是 | E21: 1 | F21: NEW-D1-交运-远东干散货-自动化 | G21: =VLOOKUP(F21,B:E,4,0) -> 1
A22: 1-行业经济 | B22: NEW-D1-交运-远东干散货-自动化 | C22: 日 | D22: 是 | E22: 1 | F22: NEW-D1-交运-集装箱期租-自动化 | G22: =VLOOKUP(F22,B:E,4,0) -> 1
A23: 1-行业经济 | B23: NEW-D1-交运-集装箱期租-自动化 | C23: 日 | D23: 是 | E23: 1 | F23: NEW-D2-交运-地铁客运量-全国物流-人工 | G23: =VLOOKUP(F23,B:E,4,0) -> 1
A24: 1-行业经济 | B24: NEW-D2-交运-地铁客运量-全国物流-人工 | C24: 日 | D24: 是 | E24: 1 | F24: NEW-D2-交运-地铁客运量-地铁23城客运量-人工 | G24: =VLOOKUP(F24,B:E,4,0) -> 1
A25: 1-行业经济 | B25: NEW-D2-交运-地铁客运量-地铁23城客运量-人工 | C25: 日 | D25: 否 | E25: =VLOOKUP(C25,H:I,2,0) -> 1 | F25: NEW-D2-交运-地铁客运量-地铁客运量-自动化 | G25: =VLOOKUP(F25,B:E,4,0) -> 1
A26: 1-行业经济 | B26: NEW-D2-交运-地铁客运量-地铁客运量-自动化 | C26: 日 | D26: 是 | E26: 1 | F26: NEW-D3-交运-高德交通-城市交通(日)-人工 | G26: =VLOOKUP(F26,B:E,4,0) -> 1
A27: 1-行业经济 | B27: NEW-D3-交运-高德交通-城市交通(日)-人工 | C27: 日 | D27: 是 | E27: 1 | F27: NEW-D3-交运-高德交通-百城拥堵延时指数-人工 | G27: =VLOOKUP(F27,B:E,4,0) -> 1
A28: 1-行业经济 | B28: NEW-D3-交运-高德交通-百城拥堵延时指数-人工 | C28: 日 | D28: 否 | E28: =VLOOKUP(C28,H:I,2,0) -> 1 | F28: NEW-D4-交运-公路货运指数-周-人工 | G28: =VLOOKUP(F28,B:E,4,0) -> 1
A29: 1-行业经济 | B29: NEW-D4-交运-公路货运指数-周-人工 | C29: 日 | D29: 是 | E29: 1 | F29: NEW-D4-交运-公路货运指数-日-人工 | G29: =VLOOKUP(F29,B:E,4,0) -> 1
A30: 1-行业经济 | B30: NEW-D4-交运-公路货运指数-日-人工 | C30: 日 | D30: 是 | E30: 1 | F30: NEW-D4-交运-公路货运指数-月-人工 | G30: =VLOOKUP(F30,B:E,4,0) -> 1
A31: 1-行业经济 | B31: NEW-D4-交运-公路货运指数-月-人工 | C31: 日 | D31: 是 | E31: 1 | F31: NEW-D5-交运-百度地图-迁徙规模指数-迁入-人工 | G31: =VLOOKUP(F31,B:E,4,0) -> 1
A32: 1-行业经济 | B32: NEW-D5-交运-百度地图-迁徙规模指数-迁入-人工 | C32: 日 | D32: 是 | E32: 1 | F32: NEW-D5-交运-百度地图-迁徙规模指数-迁出-人工 | G32: =VLOOKUP(F32,B:E,4,0) -> 1
A33: 1-行业经济 | B33: NEW-D5-交运-百度地图-迁徙规模指数-迁出-人工 | C33: 日 | D33: 是 | E33: 1 | F33: NEW-D6-交运-机场-民航运行简报-自动化 | G33: =VLOOKUP(F33,B:E,4,0) -> 1
A34: 1-行业经济 | B34: NEW-D6-交运-机场-民航运行简报-自动化 | C34: 日 | D34: 是 | E34: 1 | F34: NEW-D6-交运-机场-海口美兰国际机场客流量-人工 | G34: =VLOOKUP(F34,B:E,4,0) -> 1
A35: 1-行业经济 | B35: NEW-D6-交运-机场-海口美兰国际机场客流量-人工 | C35: 日 | D35: 是 | E35: 1 | F35: NEW-D6-交运-机场-美国各州机场运营状态-人工 | G35: =VLOOKUP(F35,B:E,4,0) -> 1
A36: 1-行业经济 | B36: NEW-D6-交运-机场-美国各州机场运营状态-人工 | C36: 日 | D36: 否 | E36: =VLOOKUP(C36,H:I,2,0) -> 1 | F36: NEW-D6-交运-机场-美国机场运营状态-自动化 | G36: =VLOOKUP(F36,B:E,4,0) -> 1
A37: 1-行业经济 | B37: NEW-D6-交运-机场-美国机场运营状态-自动化 | C37: 日 | D37: 否 | E37: =VLOOKUP(C37,H:I,2,0) -> 1 | F37: NEW-D6-交运-机场-航司飞机利用情况-人工 | G37: =VLOOKUP(F37,B:E,4,0) -> 1
A38: 1-行业经济 | B38: NEW-D6-交运-机场-航司飞机利用情况-人工 | C38: 日 | D38: 是 | E38: 1 | F38: NEW-D6-交运-机场-航班执行情况-自动化 | G38: =VLOOKUP(F38,B:E,4,0) -> 1
A39: 1-行业经济 | B39: NEW-D6-交运-机场-航班执行情况-自动化 | C39: 日 | D39: 是 | E39: 1 | F39: NEW-D7-交运-TSA安检-自动化 | G39: =VLOOKUP(F39,B:E,4,0) -> 1
A40: 1-行业经济 | B40: NEW-D7-交运-TSA安检-自动化 | C40: 日 | D40: 是 | E40: 1 | F40: NEW-D7-交运-一链通-人工 | G40: =VLOOKUP(F40,B:E,4,0) -> 1
...

Sheet Sheet1
B3: 模版频率
B4: 日 | C4: 半年 | D4: 不定期 | E4: 季 | F4: 年 | G4: 旬 | H4: 月 | I4: 周 | J4: (Blank) | K4: Grand Total
A5: 计数项:模版名称 | B5: 1927 | C5: 12 | D5: 16 | E5: 335 | F5: 2038 | G5: 17 | H5: 2982 | I5: 1138 | J5: 2333 | K5: 10798

Sheet Sheet2
C6: 频率 | D6: 任务数 | E6: 根据时效每月处理任务数 | F6: 每月人/日（按照每个任务平均1分钟计算） | G6: 加了冷静期，粗略估计
C7: 日 | D7: 1927 | E7: =D7*24 -> 46248 | F7: =E7/480 -> 96.35
C8: 半年 | D8: 12
C9: 不定期 | D9: 16
C10: 季 | D10: 335 | E10: =D10*10 -> 3350 | F10: =E10/480 -> 6.9791667
C11: 年 | D11: 2038 | E11: =D11*6 -> 12228 | F11: =E11/480 -> 25.475
C12: 旬 | D12: 17
C13: 月 | D13: 2982 | E13: =D13*10 -> 29820 | F13: =E13/480 -> 62.125 | G13: 31
C14: 周 | D14: 1138 | E14: =D14*24 -> 27312 | F14: =E14/480 -> 56.9
C15: (空白) | D15: 2333
C16: 总计 | D16: 10798 | E16: =SUM(E7:E14) -> 118958 | F16: =E16/480 -> 247.82917

Sheet Sheet3
A1: 模版名称 | F1: 核心重点指标
A2: NEW-DWMY-交运-中航信-当日预定指数-日 | F2: NEW-M1-化工-OPEC-VLCC运价指数
A3: NEW-DWMY-交运-中航信-需求指数 | F3: 国际宏观-M2-美国-劳工部-非农每周工作时间TableB-2
A4: NEW-HW1-化工-库存模板-丙酮江阴库存 | F4: NEW-M6-公用事业-杭州
A5: NEW-HW1-化工-库存模板-华东主港乙二醇库存及主流库区统计分析 | F5: NEW-M3-农林牧渔-USDA豆油供需平衡表
A6: NEW-HW1-化工-库存模板-华东乙二醇码头库存 | F6: NEW-Y1-交运-轨道交通协会-地铁
A7: NEW-HW1-化工-库存模板-苯酚江阴港口库存 | F7: 【经营数据】-汽车-M1-亚星客车
A8: NEW-D1-TMT-每日票房 | F8: 新宏观-M4-国统局-36个城市CPI分项-36个城市CPI分项
A9: NEW-D1-TMT-每日票房 | F9: 地方经济三期-Y35-云南省统计公报-普洱市
A10: NEW-D1-交运-BDI | F10: NEW-D4-化工-隆众化肥及其他-磷酸出厂价
A11: NEW-D1-交运-FDI | F11: NEW-M15-化工-隆众月报-4
A12: NEW-D1-交运-中国水运网运价 | F12: 新宏观-M3-海关总署-全国出口商品贸易同比指数(HS4分类)
... A5498: 地方经济运行-M1-新疆(非重点)-新疆 | F5498: 【经营数据】-食品饮料-Q1-海天味业
A5499: 地方经济运行-M1-新疆(非重点)-昌吉回族
A5500: 地方经济运行-M1-新疆(非重点)-昌吉回族区县
A5501: 地方经济运行-M1-新疆(非重点)-石河子
A5502: 地方经济运行-M1-新疆(非重点)-阿克苏
A5503: 地方经济运行-M1-新疆(非重点)-阿克苏区县
A5504: 地方经济运行-M1-新疆(非重点)-阿勒泰区县
A5505: 地方经济运行-M1-新疆(非重点)-阿拉尔市
A5506: 地方经济运行-M1-无锡市-宜兴市
A5507: 地方经济运行-M1-无锡市-惠山区
A5508: 地方经济运行-M1-无锡市-无锡
A5509: 地方经济运行-M1-无锡市-无锡市专利交通邮政
A5510: 地方经济运行-M1-无锡市-无锡市其他
... A10799: 衍生指标-NEW-海关新增指标模板
